[2025-06-27T16:37:15.770+0000] {taskinstance.py:1159} INFO - Dependencies all met for dep_context=non-requeueable deps ti=<TaskInstance: our_first_dag_v_05.greet scheduled__2024-06-07T00:00:00+00:00 [queued]>
[2025-06-27T16:37:15.790+0000] {taskinstance.py:1159} INFO - Dependencies all met for dep_context=requeueable deps ti=<TaskInstance: our_first_dag_v_05.greet scheduled__2024-06-07T00:00:00+00:00 [queued]>
[2025-06-27T16:37:15.791+0000] {taskinstance.py:1361} INFO - Starting attempt 2 of 6
[2025-06-27T16:37:15.816+0000] {taskinstance.py:1382} INFO - Executing <Task(PythonOperator): greet> on 2024-06-07 00:00:00+00:00
[2025-06-27T16:37:15.831+0000] {standard_task_runner.py:57} INFO - Started process 4546 to run task
[2025-06-27T16:37:15.840+0000] {standard_task_runner.py:84} INFO - Running: ['***', 'tasks', 'run', 'our_first_dag_v_05', 'greet', 'scheduled__2024-06-07T00:00:00+00:00', '--job-id', '1712', '--raw', '--subdir', 'DAGS_FOLDER/create_dag_with_python_0perator.py', '--cfg-path', '/tmp/tmpdv4zrsyc']
[2025-06-27T16:37:15.845+0000] {standard_task_runner.py:85} INFO - Job 1712: Subtask greet
[2025-06-27T16:37:15.944+0000] {task_command.py:416} INFO - Running <TaskInstance: our_first_dag_v_05.greet scheduled__2024-06-07T00:00:00+00:00 [running]> on host a8edfe6283f3
[2025-06-27T16:37:16.072+0000] {taskinstance.py:1662} INFO - Exporting env vars: AIRFLOW_CTX_DAG_OWNER='shivanshu' AIRFLOW_CTX_DAG_ID='our_first_dag_v_05' AIRFLOW_CTX_TASK_ID='greet' AIRFLOW_CTX_EXECUTION_DATE='2024-06-07T00:00:00+00:00' AIRFLOW_CTX_TRY_NUMBER='2' AIRFLOW_CTX_DAG_RUN_ID='scheduled__2024-06-07T00:00:00+00:00'
[2025-06-27T16:37:16.074+0000] {taskinstance.py:1937} ERROR - Task failed with exception
Traceback (most recent call last):
  File "/home/airflow/.local/lib/python3.8/site-packages/airflow/operators/python.py", line 192, in execute
    return_value = self.execute_callable()
  File "/home/airflow/.local/lib/python3.8/site-packages/airflow/operators/python.py", line 209, in execute_callable
    return self.python_callable(*self.op_args, **self.op_kwargs)
  File "/opt/airflow/dags/create_dag_with_python_0perator.py", line 15, in greet
    first_name=ti.xcom_pull(task_ids='get_name',keys='first_name')
  File "/home/airflow/.local/lib/python3.8/site-packages/airflow/utils/session.py", line 77, in wrapper
    return func(*args, session=session, **kwargs)
TypeError: xcom_pull() got an unexpected keyword argument 'keys'
[2025-06-27T16:37:16.088+0000] {taskinstance.py:1400} INFO - Marking task as UP_FOR_RETRY. dag_id=our_first_dag_v_05, task_id=greet, execution_date=20240607T000000, start_date=20250627T163715, end_date=20250627T163716
[2025-06-27T16:37:16.103+0000] {standard_task_runner.py:104} ERROR - Failed to execute job 1712 for task greet (xcom_pull() got an unexpected keyword argument 'keys'; 4546)
[2025-06-27T16:37:16.138+0000] {local_task_job_runner.py:228} INFO - Task exited with return code 1
[2025-06-27T16:37:16.166+0000] {taskinstance.py:2778} INFO - 0 downstream tasks scheduled from follow-on schedule check
