[2025-06-27T16:30:26.592+0000] {taskinstance.py:1159} INFO - Dependencies all met for dep_context=non-requeueable deps ti=<TaskInstance: our_first_dag_v_06.get_name scheduled__2024-08-30T00:00:00+00:00 [queued]>
[2025-06-27T16:30:26.620+0000] {taskinstance.py:1159} INFO - Dependencies all met for dep_context=requeueable deps ti=<TaskInstance: our_first_dag_v_06.get_name scheduled__2024-08-30T00:00:00+00:00 [queued]>
[2025-06-27T16:30:26.621+0000] {taskinstance.py:1361} INFO - Starting attempt 1 of 6
[2025-06-27T16:30:26.761+0000] {taskinstance.py:1382} INFO - Executing <Task(PythonOperator): get_name> on 2024-08-30 00:00:00+00:00
[2025-06-27T16:30:26.788+0000] {standard_task_runner.py:57} INFO - Started process 4098 to run task
[2025-06-27T16:30:26.803+0000] {standard_task_runner.py:84} INFO - Running: ['***', 'tasks', 'run', 'our_first_dag_v_06', 'get_name', 'scheduled__2024-08-30T00:00:00+00:00', '--job-id', '1622', '--raw', '--subdir', 'DAGS_FOLDER/create_dag_with_python_0perator.py', '--cfg-path', '/tmp/tmpmm82evvq']
[2025-06-27T16:30:26.814+0000] {standard_task_runner.py:85} INFO - Job 1622: Subtask get_name
[2025-06-27T16:30:26.993+0000] {task_command.py:416} INFO - Running <TaskInstance: our_first_dag_v_06.get_name scheduled__2024-08-30T00:00:00+00:00 [running]> on host a8edfe6283f3
[2025-06-27T16:30:27.253+0000] {taskinstance.py:1662} INFO - Exporting env vars: AIRFLOW_CTX_DAG_OWNER='shivanshu' AIRFLOW_CTX_DAG_ID='our_first_dag_v_06' AIRFLOW_CTX_TASK_ID='get_name' AIRFLOW_CTX_EXECUTION_DATE='2024-08-30T00:00:00+00:00' AIRFLOW_CTX_TRY_NUMBER='1' AIRFLOW_CTX_DAG_RUN_ID='scheduled__2024-08-30T00:00:00+00:00'
[2025-06-27T16:30:27.257+0000] {taskinstance.py:1937} ERROR - Task failed with exception
Traceback (most recent call last):
  File "/home/airflow/.local/lib/python3.8/site-packages/airflow/operators/python.py", line 192, in execute
    return_value = self.execute_callable()
  File "/home/airflow/.local/lib/python3.8/site-packages/airflow/operators/python.py", line 209, in execute_callable
    return self.python_callable(*self.op_args, **self.op_kwargs)
  File "/opt/airflow/dags/create_dag_with_python_0perator.py", line 19, in get_name
    ti.xcom_push(key='first_name')
  File "/home/airflow/.local/lib/python3.8/site-packages/airflow/utils/session.py", line 77, in wrapper
    return func(*args, session=session, **kwargs)
TypeError: xcom_push() missing 1 required positional argument: 'value'
[2025-06-27T16:30:27.281+0000] {taskinstance.py:1400} INFO - Marking task as UP_FOR_RETRY. dag_id=our_first_dag_v_06, task_id=get_name, execution_date=20240830T000000, start_date=20250627T163026, end_date=20250627T163027
[2025-06-27T16:30:27.313+0000] {standard_task_runner.py:104} ERROR - Failed to execute job 1622 for task get_name (xcom_push() missing 1 required positional argument: 'value'; 4098)
[2025-06-27T16:30:27.322+0000] {local_task_job_runner.py:228} INFO - Task exited with return code 1
[2025-06-27T16:30:27.410+0000] {taskinstance.py:2778} INFO - 0 downstream tasks scheduled from follow-on schedule check
