[2025-06-29T15:10:13.971+0000] {taskinstance.py:1159} INFO - Dependencies all met for dep_context=non-requeueable deps ti=<TaskInstance: dag_with_python_dependencies_v01.get_sklearn scheduled__2022-01-12T00:00:00+00:00 [queued]>
[2025-06-29T15:10:14.000+0000] {taskinstance.py:1159} INFO - Dependencies all met for dep_context=requeueable deps ti=<TaskInstance: dag_with_python_dependencies_v01.get_sklearn scheduled__2022-01-12T00:00:00+00:00 [queued]>
[2025-06-29T15:10:14.001+0000] {taskinstance.py:1361} INFO - Starting attempt 1 of 1
[2025-06-29T15:10:14.131+0000] {taskinstance.py:1382} INFO - Executing <Task(PythonOperator): get_sklearn> on 2022-01-12 00:00:00+00:00
[2025-06-29T15:10:14.171+0000] {standard_task_runner.py:57} INFO - Started process 5624 to run task
[2025-06-29T15:10:14.205+0000] {standard_task_runner.py:84} INFO - Running: ['***', 'tasks', 'run', 'dag_with_python_dependencies_v01', 'get_sklearn', 'scheduled__2022-01-12T00:00:00+00:00', '--job-id', '4429', '--raw', '--subdir', 'DAGS_FOLDER/dag_with_python_dependencies.py', '--cfg-path', '/tmp/tmp21tqhnwz']
[2025-06-29T15:10:14.217+0000] {standard_task_runner.py:85} INFO - Job 4429: Subtask get_sklearn
[2025-06-29T15:10:14.461+0000] {task_command.py:416} INFO - Running <TaskInstance: dag_with_python_dependencies_v01.get_sklearn scheduled__2022-01-12T00:00:00+00:00 [running]> on host f561bfe7dd3a
[2025-06-29T15:10:14.928+0000] {taskinstance.py:1662} INFO - Exporting env vars: AIRFLOW_CTX_DAG_OWNER='shivanshu' AIRFLOW_CTX_DAG_ID='dag_with_python_dependencies_v01' AIRFLOW_CTX_TASK_ID='get_sklearn' AIRFLOW_CTX_EXECUTION_DATE='2022-01-12T00:00:00+00:00' AIRFLOW_CTX_TRY_NUMBER='1' AIRFLOW_CTX_DAG_RUN_ID='scheduled__2022-01-12T00:00:00+00:00'
[2025-06-29T15:10:14.935+0000] {taskinstance.py:1937} ERROR - Task failed with exception
Traceback (most recent call last):
  File "/home/airflow/.local/lib/python3.8/site-packages/airflow/operators/python.py", line 192, in execute
    return_value = self.execute_callable()
  File "/home/airflow/.local/lib/python3.8/site-packages/airflow/operators/python.py", line 209, in execute_callable
    return self.python_callable(*self.op_args, **self.op_kwargs)
  File "/opt/airflow/dags/dag_with_python_dependencies.py", line 15, in get_sklearn
    import sklearn
ModuleNotFoundError: No module named 'sklearn'
[2025-06-29T15:10:14.959+0000] {taskinstance.py:1400} INFO - Marking task as FAILED. dag_id=dag_with_python_dependencies_v01, task_id=get_sklearn, execution_date=20220112T000000, start_date=20250629T151013, end_date=20250629T151014
[2025-06-29T15:10:14.986+0000] {standard_task_runner.py:104} ERROR - Failed to execute job 4429 for task get_sklearn (No module named 'sklearn'; 5624)
[2025-06-29T15:10:15.050+0000] {local_task_job_runner.py:228} INFO - Task exited with return code 1
[2025-06-29T15:10:15.109+0000] {taskinstance.py:2778} INFO - 0 downstream tasks scheduled from follow-on schedule check
