[2025-06-27T16:25:51.020+0000] {taskinstance.py:1159} INFO - Dependencies all met for dep_context=non-requeueable deps ti=<TaskInstance: our_first_dag_v_06.greet scheduled__2024-06-07T00:00:00+00:00 [queued]>
[2025-06-27T16:25:51.097+0000] {taskinstance.py:1159} INFO - Dependencies all met for dep_context=requeueable deps ti=<TaskInstance: our_first_dag_v_06.greet scheduled__2024-06-07T00:00:00+00:00 [queued]>
[2025-06-27T16:25:51.097+0000] {taskinstance.py:1361} INFO - Starting attempt 1 of 6
[2025-06-27T16:25:51.273+0000] {taskinstance.py:1382} INFO - Executing <Task(PythonOperator): greet> on 2024-06-07 00:00:00+00:00
[2025-06-27T16:25:51.338+0000] {standard_task_runner.py:57} INFO - Started process 3604 to run task
[2025-06-27T16:25:51.347+0000] {standard_task_runner.py:84} INFO - Running: ['***', 'tasks', 'run', 'our_first_dag_v_06', 'greet', 'scheduled__2024-06-07T00:00:00+00:00', '--job-id', '1458', '--raw', '--subdir', 'DAGS_FOLDER/create_dag_with_python_0perator.py', '--cfg-path', '/tmp/tmp58djqobf']
[2025-06-27T16:25:51.373+0000] {standard_task_runner.py:85} INFO - Job 1458: Subtask greet
[2025-06-27T16:25:51.642+0000] {task_command.py:416} INFO - Running <TaskInstance: our_first_dag_v_06.greet scheduled__2024-06-07T00:00:00+00:00 [running]> on host a8edfe6283f3
[2025-06-27T16:25:52.225+0000] {taskinstance.py:1662} INFO - Exporting env vars: AIRFLOW_CTX_DAG_OWNER='shivanshu' AIRFLOW_CTX_DAG_ID='our_first_dag_v_06' AIRFLOW_CTX_TASK_ID='greet' AIRFLOW_CTX_EXECUTION_DATE='2024-06-07T00:00:00+00:00' AIRFLOW_CTX_TRY_NUMBER='1' AIRFLOW_CTX_DAG_RUN_ID='scheduled__2024-06-07T00:00:00+00:00'
[2025-06-27T16:25:52.227+0000] {taskinstance.py:1937} ERROR - Task failed with exception
Traceback (most recent call last):
  File "/home/airflow/.local/lib/python3.8/site-packages/airflow/operators/python.py", line 192, in execute
    return_value = self.execute_callable()
  File "/home/airflow/.local/lib/python3.8/site-packages/airflow/operators/python.py", line 209, in execute_callable
    return self.python_callable(*self.op_args, **self.op_kwargs)
  File "/opt/airflow/dags/create_dag_with_python_0perator.py", line 15, in greet
    name=ti.xcoms_pull(task_ids='get_name')
AttributeError: 'TaskInstance' object has no attribute 'xcoms_pull'
[2025-06-27T16:25:52.319+0000] {taskinstance.py:1400} INFO - Marking task as UP_FOR_RETRY. dag_id=our_first_dag_v_06, task_id=greet, execution_date=20240607T000000, start_date=20250627T162551, end_date=20250627T162552
[2025-06-27T16:25:52.439+0000] {standard_task_runner.py:104} ERROR - Failed to execute job 1458 for task greet ('TaskInstance' object has no attribute 'xcoms_pull'; 3604)
[2025-06-27T16:25:52.682+0000] {local_task_job_runner.py:228} INFO - Task exited with return code 1
[2025-06-27T16:25:52.816+0000] {taskinstance.py:2778} INFO - 0 downstream tasks scheduled from follow-on schedule check
