[2025-06-27T16:24:18.788+0000] {taskinstance.py:1159} INFO - Dependencies all met for dep_context=non-requeueable deps ti=<TaskInstance: our_first_dag_v_03.greet scheduled__2024-11-23T00:00:00+00:00 [queued]>
[2025-06-27T16:24:18.862+0000] {taskinstance.py:1159} INFO - Dependencies all met for dep_context=requeueable deps ti=<TaskInstance: our_first_dag_v_03.greet scheduled__2024-11-23T00:00:00+00:00 [queued]>
[2025-06-27T16:24:18.862+0000] {taskinstance.py:1361} INFO - Starting attempt 1 of 6
[2025-06-27T16:24:19.170+0000] {taskinstance.py:1382} INFO - Executing <Task(PythonOperator): greet> on 2024-11-23 00:00:00+00:00
[2025-06-27T16:24:19.399+0000] {standard_task_runner.py:57} INFO - Started process 3474 to run task
[2025-06-27T16:24:19.463+0000] {standard_task_runner.py:84} INFO - Running: ['***', 'tasks', 'run', 'our_first_dag_v_03', 'greet', 'scheduled__2024-11-23T00:00:00+00:00', '--job-id', '1414', '--raw', '--subdir', 'DAGS_FOLDER/create_dag_with_python_0perator.py', '--cfg-path', '/tmp/tmprzc1l9p_']
[2025-06-27T16:24:19.548+0000] {standard_task_runner.py:85} INFO - Job 1414: Subtask greet
[2025-06-27T16:24:20.750+0000] {task_command.py:416} INFO - Running <TaskInstance: our_first_dag_v_03.greet scheduled__2024-11-23T00:00:00+00:00 [running]> on host a8edfe6283f3
[2025-06-27T16:24:23.235+0000] {taskinstance.py:1662} INFO - Exporting env vars: AIRFLOW_CTX_DAG_OWNER='shivanshu' AIRFLOW_CTX_DAG_ID='our_first_dag_v_03' AIRFLOW_CTX_TASK_ID='greet' AIRFLOW_CTX_EXECUTION_DATE='2024-11-23T00:00:00+00:00' AIRFLOW_CTX_TRY_NUMBER='1' AIRFLOW_CTX_DAG_RUN_ID='scheduled__2024-11-23T00:00:00+00:00'
[2025-06-27T16:24:23.296+0000] {taskinstance.py:1937} ERROR - Task failed with exception
Traceback (most recent call last):
  File "/home/airflow/.local/lib/python3.8/site-packages/airflow/operators/python.py", line 192, in execute
    return_value = self.execute_callable()
  File "/home/airflow/.local/lib/python3.8/site-packages/airflow/operators/python.py", line 209, in execute_callable
    return self.python_callable(*self.op_args, **self.op_kwargs)
  File "/opt/airflow/dags/create_dag_with_python_0perator.py", line 15, in greet
    name=ti.xcoms_pull(task_ids='get_name')
AttributeError: 'TaskInstance' object has no attribute 'xcoms_pull'
[2025-06-27T16:24:23.508+0000] {taskinstance.py:1400} INFO - Marking task as UP_FOR_RETRY. dag_id=our_first_dag_v_03, task_id=greet, execution_date=20241123T000000, start_date=20250627T162418, end_date=20250627T162423
[2025-06-27T16:24:24.295+0000] {standard_task_runner.py:104} ERROR - Failed to execute job 1414 for task greet ('TaskInstance' object has no attribute 'xcoms_pull'; 3474)
[2025-06-27T16:24:24.766+0000] {local_task_job_runner.py:228} INFO - Task exited with return code 1
[2025-06-27T16:24:25.009+0000] {taskinstance.py:2778} INFO - 0 downstream tasks scheduled from follow-on schedule check
